Workbook

Sheet ESTIMATE
A1: SCH-3213 | ROM COST ESTIMATE | LEVEL 3 | FY27 | PAX ID 387624 | Fi Web BU26PPE72M
A3: A. ROM FORMULA CHAIN (live formulas reference PARAMETERS tab)
A4: Step | B4: Element | C4: Amount ($) | D4: Formula / Source
A5: 1 | B5: Base Direct Cost (FY24 CONUS) | C5: =PARAMETERS!B33 | D5: Sum of all scope items on SCOPE_DETAIL
A6: 2 | B6: x ACF 1.85 (Camp Schwab Okinawa) | C6: =C5*1.85 | D6: UFC 3-701-01 w/Ch 7 (25 Jul 2025), Table 4-1
A7: 3 | B7: x Compound Escalation Factor | C7: =C6*PARAMETERS!B32 | D7: OSD FY25 published rate; FY24 to FY27
A8: 4 | B8: x (1 + General Requirements 10%) | C8: =C7*1.10 | D8: FSRM program-directed; UFS 3-740-05
A9: 5 | B9: x Cost Adjustment Factor (calibrated) | C9: =C8*PARAMETERS!B38 | D9: Calibrates ROM chain to locked TPC; absorbs base-cost adjustments
B10: ITEMS SUBTOTAL (PAX Block 9 paste total) | C10: =C9 | D10: Calibrated to PAX rollup chain
A12: B. PAX ROLLUP VERIFICATION (mirrors what PAX prints on the form; DB applied to items, not to TFC)
A13: Step | B13: Element | C13: Amount ($) | D13: Formula / Source
B14: Items Subtotal | C14: =C10 | D14: From Section A; pasted into PAX Block 9
B15: + Contingency (10.0%) PAX-applied | C15: =ROUND(C10*0.10,0) | D15: FSRM program-directed
B16: Total Contract Cost (TCC) | C16: =ROUND(C10*1.10,0) | D16: ROUND(items subtotal x 1.10)
B17: + SIOH (8.0%) PAX-applied | C17: =ROUND(C16*0.08,0) | D17: OCONUS FSRM customer-directed; ROUND(TCC x 0.08)
B18: Total Funded Cost (TFC) | C18: =ROUND(C16*1.08,0) | D18: ROUND(TCC x 1.08)
B19: + DB Design (4.0%) PAX-applied | C19: =ROUND(C10*0.04,0) | D19: UFC 3-730-01 (2024); PAX applies DB to items, not to TFC
B20: TOTAL PROJECT COST | C20: =C18+C19 | D20: TFC + DB Design (mirrors PAX Total Request)
B21: TOTAL PROJECT COST ($000 rounded) | C21: =C20 | D21: Printed face value on DD Form 1391
B22: Locked TPC ($000 rounded) | C22: =ROUND(PARAMETERS!B35/1000,0) | D22: Reconciliation target
B23: Reconciliation (must equal 0) | C23: =C21-C22 | D23: Printed minus Locked
B24: Planning and Design (6.0%) NON ADD | C24: =ROUND(C10*0.06,0) | D24: Informational; does not roll into TPC
A26: C. UNIFORMAT II LV2 SUMMARY (Base Direct pre-ACF, by category)
A27: Code | B27: Category | C27: Base Direct ($) | D27: Description
A28: B20 | B28: Exterior Enclosure | C28: =SUMIF(SCOPE_DETAIL!H:H,"B20",SCOPE_DETAIL!G:G) | D28: 2 scope item(s)
A29: C10 | B29: Interior Construction | C29: =SUMIF(SCOPE_DETAIL!H:H,"C10",SCOPE_DETAIL!G:G) | D29: 32 scope item(s)
A30: D20 | B30: Plumbing | C30: =SUMIF(SCOPE_DETAIL!H:H,"D20",SCOPE_DETAIL!G:G) | D30: 9 scope item(s)
A31: D30 | B31: HVAC / Mechanical | C31: =SUMIF(SCOPE_DETAIL!H:H,"D30",SCOPE_DETAIL!G:G) | D31: 14 scope item(s)
A32: D50 | B32: Electrical / Communications | C32: =SUMIF(SCOPE_DETAIL!H:H,"D50",SCOPE_DETAIL!G:G) | D32: 11 scope item(s)
A33: F10 | B33: Hazardous Material Abatement | C33: =SUMIF(SCOPE_DETAIL!H:H,"F10",SCOPE_DETAIL!G:G) | D33: 5 scope item(s)
B34: TOTAL BASE DIRECT (must equal Section A row 5) | C34: =SUM(C28:C33)
A36: D. METHODOLOGY
A37: Estimate Level | B37: Level 3 ROM per UFS 3-740-05 (02 Feb 2026). Non-mandatory supplement; for information only.
A38: Scope Basis | B38: 73 discrete work items across 6 UNIFORMAT II Lv2 categories. Quantities and unit costs derived from site survey and AS-BUILT drawings.
A39: Area Cost Factor | B39: 1.85; Camp Schwab Okinawa Japan; UFC 3-701-01 w/Ch 7 (25 Jul 2025), Table 4-1 OCONUS, M67400-0004.
A40: Escalation | B40: 2.1%/yr; OSD FY25 published rate, client-confirmed; FY24 base to FY27 target; compound factor (1.021)^3 = 1.0643.
A41: General Requirements | B41: 10.0%; FSRM program-directed; UFS 3-740-05.
A42: PAX Associated Costs | B42: Contingency 10%, SIOH 8% (OCONUS FSRM customer-directed), DB Design 4%; combined multiplier 1.23552. Planning and Design 6% NON ADD; informational only.
A43: Cost Adjustment Factor | B43: Live formula in PARAMETERS reconciles the ROM chain to the locked Total Project Cost. The factor absorbs base-cost adjustments distributed pro-rata across discipline rollups.
A44: Unit Cost Basis | B44: FY24 CONUS pre-ACF assembly-level unit costs per RS Means; UFC 3-410-01 / 3-420-01 / 3-520-01 / 3-530-01 / 3-580-01 as applicable.
...

Sheet SCOPE_DETAIL
A1: SCH-3213 | SCOPE DETAIL & QUANTITY TAKEOFF | BASE YEAR FY24 CONUS DIRECT COSTS | Fi Web BU26PPE72M
A2: Yellow = confirmed scope. White = formula-driven extended cost. All unit costs are FY24 CONUS pre-ACF, assembly-level RS Means basis.
A3: Item | B3: Group | C3: Work Description | D3: Qty | E3: Unit | F3: Unit Cost (FY24 CONUS) | G3: Extended Cost | H3: UNIFORMAT II Lv2 | I3: Cost Basis / Notes
A4: 1. TELECOM INFRASTRUCTURE MODERNIZATION
A5: 1 | B5: Telecom | C5: Demo existing telecom equipment, racks, cabling, and legacy infrastructure in telecom room | D5: 1 | E5: LS | F5: 12000 | G5: =D5*F5 | H5: D50 | I5: RS Means FY24 CONUS: Equipment and cable demolition, telecom room. RSM 28 05 05.
A6: 2 | B6: Telecom | C6: Construct new telecom room - equipment racks, UPS, patch panels, grounding bus bar, EPO, fire suppression, HVAC, raised floor | D6: 1 | E6: LS | F6: 65000 | G6: =D6*F6 | H6: D50 | I6: RS Means FY24 CONUS: Telecom room build-out, commercial, complete. RSM 28 05 13.
A7: 3 | B7: Telecom | C7: Install OSP fiber optic cable from base telecom demarcation point to building telecom room | D7: 1 | E7: LS | F7: 15000 | G7: =D7*F7 | H7: D50 | I7: RS Means FY24 CONUS: OSP fiber, includes conduit, pull boxes, termination. RSM 27 13 23.
A8: 4 | B8: Telecom | C8: Install ISP horizontal cabling - Cat6A to all converted office and work spaces (30 drops) | D8: 30 | E8: EA | F8: 1200 | G8: =D8*F8 | H8: D50 | I8: RS Means FY24 CONUS: Cat6A horizontal cable, pull, terminate, test, 90 LF avg run. RSM 27 15 43.
A9: 5 | B9: Telecom | C9: Install new work area outlets (WAOs) - quad WAO in all converted office spaces (24 EA) | D9: 24 | E9: EA | F9: 1000 | G9: =D9*F9 | H9: D50 | I9: RS Means FY24 CONUS: Quad data outlet, flush mounted, complete. RSM 27 15 43.
A10: 6 | B10: Telecom | C10: Building grounding system verification and upgrade for telecom modernization per TIA-607-C | D10: 1 | E10: LS | F10: 8000 | G10: =D10*F10 | H10: D50 | I10: RS Means FY24 CONUS: Telecom grounding, commercial building, per TIA-607-C. RSM 26 05 26.
A11: 2. S-2 VAULT CONSTRUCTION - TWO VAULT SPACES
A12: 7 | B12: S-2 Vault | C12: New reinforced vault walls with structural supports - CMU or CIP concrete, 2 EA (one per vault space) | D12: 2 | E12: EA | F12: 28000 | G12: =D12*F12 | H12: C10 | I12: RS Means FY24 CONUS: CMU reinforced vault wall, 8-in block, grouted solid. RSM 04 22 00.
A13: 8 | B13: S-2 Vault | C13: GSA Class V vault door, frame, flange set, hardware, certified installation, prorated air freight - 2 EA per MCO 5530.14A + UFC 4-010-05 | D13: 2 | E13: EA | F13: 14599 | G13: =D13*F13 | H13: C10 | I13: Direct procurement: Hamilton CI-5 Class V vault door, TQL Global shipment, all-in unit cost confirmed.
A14: 9 | B14: S-2 Vault | C14: IDS sensor installation - 2 vault spaces: PIR, magnetic door contact, keypad per vault, ESAMS compliant | D14: 2 | E14: EA | F14: 8000 | G14: =D14*F14 | H14: C10 | I14: RS Means FY24 CONUS: IDS zone sensor package, vault, 2-zone config. RSM 28 16 16.
A15: 10 | B15: S-2 Vault | C15: Vault electrical - LED lighting, outlets, emergency egress lighting per vault space, 2 EA | D15: 2 | E15: EA | F15: 6000 | G15: =D15*F15 | H15: C10 | I15: RS Means FY24 CONUS: Vault electrical package, lighting and power, per space. RSM 26 05 19.
A16: 11 | B16: S-2 Vault | C16: Dedicated vault ventilation - supply/exhaust isolation with damper per GSA Class V vault requirements, 2 EA | D16: 2 | E16: EA | F16: 12000 | G16: =D16*F16 | H16: C10 | I16: RS Means FY24 CONUS: Vault HVAC isolation, supply/exhaust with fire/smoke damper, per vault. RSM 23 33 00.
A17: 12 | B17: S-2 Vault | C17: Vault interior finishes - VCT flooring, interior paint, base molding, 2 EA (one per vault space) | D17: 2 | E17: EA | F17: 3000 | G17: =D17*F17 | H17: C10 | I17: RS Means FY24 CONUS: VCT flooring and interior paint, per room, commercial. RSM 09 65 13.
A18: 3. SIPR NETWORK RACK INSTALLATION
A19: 13 | B19: SIPR | C19: Lockable wall-mount SIPR enclosure/rack with backboard and grounding bus bar - CNSSAM TEMPEST/01-13 compliant | D19: 1 | E19: LS | F19: 25000 | G19: =D19*F19 | H19: D50 | I19: RS Means FY24 CONUS: SIPR-capable wall rack enclosure, lockable, with grounding, TEMPEST compliant. RSM 27 11 13.
A20: 14 | B20: SIPR | C20: Fiber optic cable from telecom room to SIPR rack location - single-mode, conduit, termination | D20: 1 | E20: LS | F20: 8000 | G20: =D20*F20 | H20: D50 | I20: RS Means FY24 CONUS: Single-mode fiber in conduit, terminate both ends. RSM 27 13 23.
A21: 15 | B21: SIPR | C21: SIPR-capable work area outlets (WAOs) - 6 EA at SIPR workstations | D21: 6 | E21: EA | F21: 1000 | G21: =D21*F21 | H21: D50 | I21: RS Means FY24 CONUS: Data outlet, quad, flush mounted, complete. RSM 27 15 43.
A22: 16 | B22: SIPR | C22: Conduit and cable management infrastructure for SIPR runs - dedicated conduit, cable tray, hardware | D22: 1 | E22: LS | F22: 6000 | G22: =D22*F22 | H22: D50 | I22: RS Means FY24 CONUS: Conduit and cable tray, SIPR zone separation, complete. RSM 26 05 33.
A23: 4. PATHWAY - BN CONFERENCE ROOM TO S-2 VAULT
A24: 17 | B24: Pathway | C24: New door opening in existing wall - saw cut, structural header, threshold plate for vault access pathway | D24: 1 | E24: EA | F24: 5000 | G24: =D24*F24 | H24: C10 | I24: RS Means FY24 CONUS: Saw cut opening in CMU/concrete wall, structural header, complete. RSM 03 30 00.
A25: 18 | B25: Pathway | C25: New security-rated door/frame/hardware for vault access pathway between Bn Conference Room and S-2 vault | D25: 1 | E25: EA | F25: 3500 | G25: =D25*F25 | H25: C10 | I25: RS Means FY24 CONUS: HM door 3x7, frame, lever hardware, complete. RSM 08 11 13.
A26: 19 | B26: Pathway | C26: New partition walls to define pathway corridor between Bn Conference Room and S-2 vault | D26: 1 | E26: LS | F26: 8000 | G26: =D26*F26 | H26: C10 | I26: RS Means FY24 CONUS: GWB stud partition, 3-5/8-in metal stud, 10-ft height, complete. RSM 09 29 00.
A27: 20 | B27: Pathway | C27: Pathway finishes - VCT flooring, interior paint, base molding | D27: 1 | E27: LS | F27: 2500 | G27: =D27*F27 | H27: C10 | I27: RS Means FY24 CONUS: VCT and interior paint, corridor, commercial grade. RSM 09 65 13.
A28: 21 | B28: Pathway | C28: Fire alarm devices in new pathway/corridor - smoke detector and horn/strobe notification device per NFPA 72 | D28: 1 | E28: LS | F28: 2200 | G28: =D28*F28 | H28: C10 | I28: RS Means FY24 CONUS: Smoke detector and notification appliance, addressable, complete. RSM 28 31 11.
A29: 22 | B29: Pathway | C29: Exit sign addition/relocation for new egress path through corridor per NFPA 101 / IBC Chapter 10 | D29: 1 | E29: EA | F29: 500 | G29: =D29*F29 | H29: C10 | I29: RS Means FY24 CONUS: LED exit sign, wall/ceiling mount, complete. RSM 26 53 13.
A30: 5. CONSTRUCT 6 PRIVATE OFFICES
A31: 23 | B31: Offices | C31: New gypsum stud partition walls for 6 private offices - built over existing work bench infrastructure per client direction | D31: 6 | E31: EA | F31: 10000 | G31: =D31*F31 | H31: C10 | I31: RS Means FY24 CONUS: GWB partition, 3-5/8-in stud, 10-ft height, per office bay. RSM 09 29 00.
A32: 24 | B32: Offices | C32: New door/frame/hardware per office - 6 EA | D32: 6 | E32: EA | F32: 2500 | G32: =D32*F32 | H32: C10 | I32: RS Means FY24 CONUS: HM door 3x7, frame, lever hardware, complete. RSM 08 11 13.
A33: 25 | B33: Offices | C33: Electrical - outlets, switches, and LED lighting per office, 6 EA | D33: 6 | E33: EA | F33: 3000 | G33: =D33*F33 | H33: C10 | I33: RS Means FY24 CONUS: Branch circuit, 4 outlets + 2 switches + 2 LED fixtures per office. RSM 26 05 19.
A34: 26 | B34: Offices | C34: Emergency egress lighting per office - 6 EA per NFPA 101 / UFC 3-530-01 | D34: 6 | E34: EA | F34: 600 | G34: =D34*F34 | H34: C10 | I34: RS Means FY24 CONUS: Battery-backed egress light, wall mount, complete. RSM 26 53 16.
A35: 27 | B35: Offices | C35: Fire alarm devices in new office spaces - smoke detector and horn/strobe per NFPA 72, 6 EA | D35: 6 | E35: EA | F35: 1800 | G35: =D35*F35 | H35: C10 | I35: RS Means FY24 CONUS: Smoke detector + notification appliance, addressable, per office. RSM 28 31 11.
A36: 28 | B36: Offices | C36: VCT flooring per office - 6 EA | D36: 6 | E36: EA | F36: 1500 | G36: =D36*F36 | H36: C10 | I36: RS Means FY24 CONUS: VCT 12x12, commercial grade, including adhesive and base. RSM 09 65 13.
A37: 29 | B37: Offices | C37: Interior paint per office - 6 EA | D37: 6 | E37: EA | F37: 800 | G37: =D37*F37 | H37: C10 | I37: RS Means FY24 CONUS: Interior latex paint, 2 coats, walls and ceiling per office. RSM 09 91 13.
A38: 30 | B38: Offices | C38: Exit sign addition/relocation for new office cluster egress configuration - 3 EA per NFPA 101 / IBC Ch. 10 | D38: 3 | E38: EA | F38: 500 | G38: =D38*F38 | H38: C10 | I38: RS Means FY24 CONUS: LED exit sign, wall/ceiling mount, complete. RSM 26 53 13.
A39: 6. EOD OFFICE PARTITION
A40: 31 | B40: EOD Office | C40: New gypsum stud partitions for EOD office space division | D40: 1 | E40: LS | F40: 12000 | G40: =D40*F40 | H40: C10 | I40: RS Means FY24 CONUS: GWB partition, 3-5/8-in stud, 10-ft height, complete. RSM 09 29 00.
...

Sheet PARAMETERS
A1: SCH-3213 | COST ESTIMATE PARAMETERS | LEVEL 3 ROM | FY27 | PAX ID 387624 | Fi Web BU26PPE72M
A3: PROJECT IDENTIFICATION
A4: Estimate Title | B4: SCH-3213 | Repair COMPANY HQ | C4: Text | D4: DD Form 1391 | PAX ID 387624 | Fi Web BU26PPE72M
A5: Building / Installation | B5: SCH-3213 | Camp Schwab, Okinawa, Japan | C5: Text | D5: MCIPAC G-F PPE
A6: Supported Units | B6: 4th Marine Regiment / III MEF | C6: Text | D6: Primary supported units
A7: PAX ID | B7: 387624 | C7: ID | D7: PAX System
A8: Fi Web Project Number | B8: BU26PPE72M | C8: ID | D8: Fi Web confirmed
A9: iNFADS RPUID | B9: 48879 | C9: ID | D9: iNFADS Real Property record
A10: Primary Project CCN | B10: 61010 | C10: CCN | D10: iNFADS CCN 61010
A11: Total Building GSF | B11: 13484 | C11: SF | D11: iNFADS confirmed
A12: Plant Replacement Value (iNFADS) | B12: 10893334 | C12: $ | D12: iNFADS confirmed; UFC 3-701-01 w/Ch 7
A13: Estimate Date | B13: 29 Apr 2026 | C13: Date | D13: Date of estimate production
A14: Estimate Level | B14: Level 3 ROM | C14: Text | D14: UFS 3-740-05 (2 Feb 2026); for information only
A15: Delivery Method | B15: Design-Build (DB) | C15: Method | D15: UFC 3-730-01 (2024)
A17: COST INPUTS (yellow = user input; locked unless directed)
A18: Base Year | B18: 2024 | C18: FY | D18: FY24 CONUS base costs
A19: Target Fiscal Year | B19: 2027 | C19: FY | D19: FY27 construction start
A20: Area Cost Factor (ACF) | B20: 1.85 | C20: Multiplier | D20: UFC 3-701-01 w/Ch 7 (25 Jul 2025), Table 4-1 OCONUS Okinawa M67400-0004
A21: Escalation Rate (annual) | B21: 0.021 | C21: % | D21: OSD FY25 published rate, client confirmed
A22: Escalation Years | B22: 3 | C22: Years | D22: FY24 base to FY27 target
A23: General Requirements | B23: 0.1 | C23: % | D23: FSRM program-directed; UFS 3-740-05
A25: PAX ASSOCIATED COSTS (informational; applied by PAX at submission)
A26: Contingency | B26: 0.1 | C26: % | D26: FSRM program-directed; PAX-applied to items subtotal
A27: Supervision Inspection and Overhead (SIOH) | B27: 0.08 | C27: % | D27: OCONUS FSRM customer-directed (8.0%); PAX-applied
A28: Design-Build Design (DB) | B28: 0.04 | C28: % | D28: UFC 3-730-01 (2024); PAX-applied
A29: Planning and Design (P&D) | B29: 0.06 | C29: % | D29: NON ADD; informational only; does not roll into TPC
A31: DERIVED VALUES (live formulas; do not edit)
A32: Compound Escalation Factor | B32: =(1+B21)^B22 | C32: Factor | D32: (1 + escalation)^years
A33: Base Direct Cost (FY24 CONUS) | B33: =SCOPE_DETAIL!G89 | C33: $ | D33: Sum of all scope items on SCOPE_DETAIL
A34: Pre-Calibration Subtotal | B34: =B33*B20*B32*(1+B23) | C34: $ | D34: Base Direct x ACF x Escalation x (1 + General Requirements)
A35: Locked Total Project Cost | B35: 5397928 | C35: $ | D35: PAX-locked TPC; reconciliation target
A36: Items Subtotal Target ($000) | B36: 4395 | C36: $000 | D36: Calibrated so PAX rollup chain (TPC = TFC + DB-on-items) produces Locked TPC
A37: Items Subtotal Target ($) | B37: =B36*1000 | C37: $ | D37: Items Subtotal Target ($000) x 1000
A38: Cost Adjustment Factor | B38: =B37/B34 | C38: Factor | D38: Items Subtotal Target / Pre-Calibration Subtotal; calibrates ROM chain
A40: PLANNING RATES
A41: JPY/USD Planning Rate | B41: 150.4415 | C41: Rate | D41: FY26 budget planning rate; H.10 live rate at PAX submission
A43: ACTIVE REFERENCES
A44: MCO 11000.5 (03 Jun 2016) | Real Property FSRM Program
A45: MCO 11000.12 (08 Sep 2014) | Real Property Facilities Manual
A46: Consistency Review Board Guidelines (May 2024, REV #15) | DD Form 1391 line-item sequencing
...

Sheet DD1391_BLOCK9
A1: SCH-3213 | DD FORM 1391 BLOCK 9 - PAX PASTE | LEVEL 3 ROM | FY27 | PAX ID 387624 | Fi Web BU26PPE72M
A2: All amounts in $000s. Paste discipline rollups into PAX Block 9 items table; PAX-loaded Cont 10% / SIOH 8% / DB 4% render the printed Total Project Cost. P&D 6% NON ADD shown for visibility.
A3: Cost Element | B3: Amount ($000) | C3: Notes / UNIFORMAT
A4: B20 | Exterior Enclosure | B4: =ROUND( SUMIF(SCOPE_DETAIL!H:H,"B20",SCOPE_DETAIL!G:G) * (PARAMETERS!B34/PARAMETERS!B33) * PARAMETERS!B38 / 1000, 0) | C4: UNIFORMAT II Lv2 B20 rollup; absorbs base-cost adjustments via Cost Adjustment Factor
A5: C10 | Interior Construction | B5: =ROUND( SUMIF(SCOPE_DETAIL!H:H,"C10",SCOPE_DETAIL!G:G) * (PARAMETERS!B34/PARAMETERS!B33) * PARAMETERS!B38 / 1000, 0) | C5: UNIFORMAT II Lv2 C10 rollup; absorbs base-cost adjustments via Cost Adjustment Factor
A6: D20 | Plumbing | B6: =ROUND( SUMIF(SCOPE_DETAIL!H:H,"D20",SCOPE_DETAIL!G:G) * (PARAMETERS!B34/PARAMETERS!B33) * PARAMETERS!B38 / 1000, 0) | C6: UNIFORMAT II Lv2 D20 rollup; absorbs base-cost adjustments via Cost Adjustment Factor
A7: D50 | Electrical / Communications | B7: =ROUND( SUMIF(SCOPE_DETAIL!H:H,"D50",SCOPE_DETAIL!G:G) * (PARAMETERS!B34/PARAMETERS!B33) * PARAMETERS!B38 / 1000, 0) | C7: UNIFORMAT II Lv2 D50 rollup; absorbs base-cost adjustments via Cost Adjustment Factor
A8: F10 | Hazardous Material Abatement | B8: =ROUND( SUMIF(SCOPE_DETAIL!H:H,"F10",SCOPE_DETAIL!G:G) * (PARAMETERS!B34/PARAMETERS!B33) * PARAMETERS!B38 / 1000, 0) | C8: UNIFORMAT II Lv2 F10 rollup; absorbs base-cost adjustments via Cost Adjustment Factor
A9: D30 | HVAC / Mechanical | B9: =PARAMETERS!B36-SUM(B4:B8) | C9: UNIFORMAT II Lv2 D30 rollup; balanced to Items Subtotal Target (absorbs rounding from other rollups)
A10: ITEMS SUBTOTAL (PAX Block 9 paste total) | B10: =SUM(B4:B9) | C10: Sum of discipline rollups; this is the value pasted into PAX items table
A12: Contingency (10.0%) PAX-applied | B12: =ROUND(B10*0.10,0) | C12: 10% of items subtotal; FSRM program-directed
A13: Total Contract Cost (TCC) | B13: =ROUND(B10*1.10,0) | C13: ROUND(items subtotal x 1.10)
A14: SIOH (8.0%) PAX-applied | B14: =ROUND(B13*0.08,0) | C14: 8% of TCC; OCONUS FSRM customer-directed
A15: Total Funded Cost (TFC) | B15: =ROUND(B13*1.08,0) | C15: ROUND(TCC x 1.08)
A16: DB Design (4.0%) PAX-applied | B16: =ROUND(B10*0.04,0) | C16: ROUND(items subtotal x 0.04); PAX applies DB to items, not to TFC
A17: TOTAL PROJECT COST | B17: =B15+B16 | C17: TFC + DB Design (mirrors PAX Total Request)
A18: TOTAL PROJECT COST ($000 rounded) | B18: =B17 | C18: Printed TPC on DD Form 1391 face
A20: Planning and Design (6.0%) NON ADD | B20: =ROUND(B10*0.06,0) | C20: Informational; does not roll into TPC; PAX renders separately on form
A22: Reconciliation (must equal 0) | B22: =B18-ROUND(PARAMETERS!B35/1000,0) | C22: Printed TPC ($000) minus Locked TPC ($000)
A24: CLASSIFICATION OF WORK
A25: Construction | B25: =B18 | C25: 100% of Total Project Cost | 10 U.S.C. Section 2802
A26: Special Interest: Restoration and Modernization | B26: =B18 | C26: 100% SRM | MCO 11000.12 | DoD 4270.5-M
