Workbook

Sheet ESTIMATE
A1: SCH-3270 | ROM COST ESTIMATE | LEVEL 3 | FY27 | PAX ID 387568 | Fi Web BU26PPE74M
A2: A. ROM FORMULA CHAIN - UFS 3-740-05 LEVEL 3
B3: Element | C3: Amount ($) | D3: Formula / Source
A4: 1 | B4: Base Direct Cost (FY24 CONUS) | C4: =SCOPE_DETAIL!G67 -> 792000 | D4: Sum of all scope items - SCOPE_DETAIL tab
A5: 2 | B5: x ACF 1.85 (Camp Schwab) = ACF-Adjusted Cost | C5: =C4*PARAMETERS!B18 -> 1465200 | D5: C4 x ACF 1.85 per UFC 3-701-01 w/Change 7 (25 Jul 2025), Table 4-1
A6: 3 | B6: x Compound Escalation Factor = Escalated Cost (FY27) | C6: =C5*PARAMETERS!B39 -> 1559459.6 | D6: C5 x (1.021)^3 = 1.0643 | FY24 to FY27 | OSD FY25 published rate
A7: 4 | B7: x (1 + General Requirements 10%) = Gen Req Applied | C7: =C6*(1+PARAMETERS!B21) -> 1715405.6 | D7: C6 x 1.10 | General Requirements per UFS 3-740-05
A8: 5 | B8: x (1 + Contingency 10%) = Construction Subtotal | C8: =ROUND(C7*(1+PARAMETERS!B22),0) -> 1886946 | D8: ROUND(C7 x 1.10, 0) | Level 3 ROM 10% contingency - FSRM program-directed
A9: 6 | B9: + LSH Allowance (2.5% of PRV) | C9: =PARAMETERS!B34 -> 987690 | D9: PRV $39,507,617 x 2.5% | iNFADS RPUID 1174058 | MCO 11000.12 | NAVFAC 11010.44E CH-1
B10: CONSTRUCTION BASE (Construction Subtotal + LSH) | C10: =C8+C9 -> 2874636 | D10: Construction Subtotal + LSH Allowance
A12: B. PROGRAM ADDERS
B13: Element | C13: Amount ($) | D13: Formula / Source
B14: Design (6.0%) | C14: =C10*PARAMETERS!B24 -> 172478.16 | D14: Construction Base x 6.0% | NAVFAC agency-directed
B15: SIOH (8.0% - OCONUS FSRM Customer-Directed) | C15: =C10*PARAMETERS!B25 -> 229970.88 | D15: Construction Base x 8.0% | OCONUS FSRM customer-directed rate (NOT standard 7.3%)
B16: Construction Management (4.0%) | C16: =C10*PARAMETERS!B26 -> 114985.44 | D16: Construction Base x 4.0% | NAVFAC agency-directed
B18: TOTAL FUNDED COST | C18: =ROUND(C10+C14+C15+C16,0) -> 3392070 | D18: Construction Base + Design + SIOH + CM | rounded to nearest dollar
B19: Design-Build Design (4.0%) - Applied AFTER Total Funded | C19: =C18*PARAMETERS!B27 -> 135682.8 | D19: Total Funded x 4.0% | UFC 3-730-01 (2024) | applied after Total Funded per DD1391 convention
B20: TOTAL PROJECT COST | C20: =C18+C19 -> 3527752.8 | D20: Total Funded + Design-Build Design
A22: C. COST PER SQUARE FOOT
B23: Item | C23: Amount ($) | D23: Basis
B24: Cost / Whole Building GSF (25,390 SF) | C24: =C18/PARAMETERS!B31 -> 133.59866 | D24: Total Funded / total building GSF | systems repair benchmark | LSH is dominant driver at this scope level
A26: D. UNIFORMAT II LEVEL 2 SUMMARY - Base Direct Cost (FY24 CONUS Pre-ACF)
A27: Code | B27: Category | C27: Base Direct ($) | D27: Description / Items
A28: B20 | B28: Exterior Doors | C28: =SUMIF(SCOPE_DETAIL!H:H,"B20",SCOPE_DETAIL!G:G) -> 22000 | D28: Roll-up door inspection and repair | 22 EA | 2010 vintage exterior vehicle bay doors
A29: C10 | B29: Interior Construction | C29: =SUMIF(SCOPE_DETAIL!H:H,"C10",SCOPE_DETAIL!G:G) -> 43000 | D29: Wall repair | anchor wire cable resecure | restroom remediation
A30: C30 | B30: Interior Finishes | C30: =SUMIF(SCOPE_DETAIL!H:H,"C30",SCOPE_DETAIL!G:G) -> 17500 | D30: Ceiling tile replacement | 2,500 SF mold/mildew damaged tile
A31: D20 | B31: Plumbing | C31: =SUMIF(SCOPE_DETAIL!H:H,"D20",SCOPE_DETAIL!G:G) -> 18800 | D31: Emergency eyewash/shower stations | 2F water cooler RM214
A32: D30 | B32: HVAC / Mechanical | C32: =SUMIF(SCOPE_DETAIL!H:H,"D30",SCOPE_DETAIL!G:G) -> 504800 | D32: ACP replacement (7 outdoor + 24 fan coils) | DOAS (4 units) | exhaust fans (22 EA) | hose reels (10 EA) | RM117 welding exhaust | RM114 removal | battery room | compressed air
A33: D50 | B33: Electrical / Communications | C33: =SUMIF(SCOPE_DETAIL!H:H,"D50",SCOPE_DETAIL!G:G) -> 185900 | D33: Lighting (94 fixtures) | Cat6 NIPR infrastructure (70 drops) | TR upgrades | MNS
B34: TOTAL BASE DIRECT COST (FY24 CONUS) | C34: =SUM(C28:C33) -> 792000 | D34: Must equal Base Direct C4 exactly - SUMIF verification
A36: E. ESTIMATE VERSION HISTORY
B37: Estimate Version | C37: Total Funded ($) | D37: Notes
B38: v8 (07 Mar 2026) | C38: 2374358 | D38: HVAC ACP replacement (7 units + 24 fan coils) + lighting (94 fixtures) + telecom Cat6/WAO infrastructure only
B39: v9 (19 Mar 2026) - CURRENT | C39: =C18 -> 3392070 | D39: Full mechanical scope added: DOAS (4 units) + exhaust systems (22 fans + 10 hose reels) + welding exhaust restore + battery room + compressed air + plumbing + roll-up doors (22 EA) + NIPR drops (70 EA) + MNS + architectural
B40: Delta (v9 vs v8) | C40: =C39-C38 -> 1017712 | D40: Scope expansion: full mechanical discipline + communications + architectural
A42: F. METHODOLOGY SUMMARY
B43: 1. Estimate Level | C43: Level 3 ROM per UFS 3-740-05 (2 Feb 2026), Table 2-1. Non-mandatory supplement; For Information Only. No accuracy percentage ranges cited. Site survey Feb 2026. Mechanical scope confirmed 19 Mar 2026. Communications scope and NIPR requirements confirmed 19 Mar 2026.
B44: 2. Scope Basis | C44: 42 discrete work items across 10 discipline groups: Mechanical HVAC ACP replacement, DOAS fresh air (4 units), exhaust systems (22 fans + 10 hose reels), battery room, compressed air; Plumbing (safety stations + water cooler); Exterior Doors (roll-up door repair, 22 EA); Electrical lighting (94 fixtures); Communications (Cat6 NIPR infrastructure 70 drops, TR upgrades, MNS); Architectural (ceiling tile, wall repair, restroom remediation). DD Form 1391 PAX ID 387568. iNFADS RPUID 1174058. References: AS-BUILT COMM drawings MC0513T H20 (2008); mechanical as-built drawings reviewed 19 Mar 2026; ACP equipment schedule confirmed 07 Mar 2026.
B45: 3. Area Cost Factor | C45: 1.85. Camp Schwab, Okinawa, Japan per UFC 3-701-01 w/Change 7 (25 Jul 2025), Table 4-1 OCONUS, installation M67400-0004.
B46: 4. Escalation | C46: 2.1%/yr; OSD FY25 published rate, client-confirmed. FY24 base to FY27 target = 3 years. Compound factor (1.021)^3 = 1.0643322610 (live formula in PARAMETERS B39).
...

Sheet SCOPE_DETAIL
A1: SCH-3270 | SCOPE DETAIL & QUANTITY TAKEOFF | BASE YEAR FY24 CONUS DIRECT COSTS | Fi Web BU26PPE74M
A2: Blue = confirmed scope. Black = formula. All unit costs FY24 CONUS pre-ACF. No HAZMAT scope.
A3: Item | B3: Group | C3: Work Description | D3: Qty | E3: Unit | F3: Unit Cost (FY24 CONUS) | G3: Extended Cost | H3: UNIFORMAT II Lv2 | I3: Cost Basis / Notes
A4: 1. MECHANICAL - HVAC ACP SYSTEM REPLACEMENT - 7 Outdoor Units + 24 Indoor Fan Coils + Infrastructure
A5: 1 | B5: Mech | C5: Replace VRF outdoor condensing unit ACP-1 | 50.2 KW / 14.3 tons | furnished and installed complete with refrigerant line connections, electrical connections, startup and commissioning | D5: 1 | E5: EA | F5: 23500 | G5: =D5*F5 -> 23500 | H5: D30 | I5: RS Means D3030; large commercial VRF condensing unit; UFC 3-410-01; ACP capacity confirmed 07 Mar 2026
A6: 2 | B6: Mech | C6: Replace VRF outdoor condensing unit ACP-2 | 26.2 KW / 7.4 tons | furnished and installed complete | D6: 1 | E6: EA | F6: 14500 | G6: =D6*F6 -> 14500 | H6: D30 | I6: RS Means D3030; UFC 3-410-01
A7: 3 | B7: Mech | C7: Replace VRF outdoor condensing unit ACP-3 | 40.0 KW / 11.4 tons | furnished and installed complete | D7: 1 | E7: EA | F7: 19500 | G7: =D7*F7 -> 19500 | H7: D30 | I7: RS Means D3030; UFC 3-410-01
A8: 4 | B8: Mech | C8: Replace VRF outdoor condensing unit ACP-4 | 16.0 KW / 4.5 tons | furnished and installed complete | D8: 1 | E8: EA | F8: 10000 | G8: =D8*F8 -> 10000 | H8: D30 | I8: RS Means D3030; UFC 3-410-01
A9: 5 | B9: Mech | C9: Replace VRF outdoor condensing unit ACP-5 | 40.0 KW / 11.4 tons | furnished and installed complete | D9: 1 | E9: EA | F9: 19500 | G9: =D9*F9 -> 19500 | H9: D30 | I9: RS Means D3030; UFC 3-410-01
A10: 6 | B10: Mech | C10: Replace VRF outdoor condensing unit ACP-6 | 14.0 KW / 4.0 tons | furnished and installed complete | D10: 1 | E10: EA | F10: 9500 | G10: =D10*F10 -> 9500 | H10: D30 | I10: RS Means D3030; UFC 3-410-01
A11: 7 | B11: Mech | C11: Replace mini-split condensing unit ACP-7 | 2.2 KW / 0.6 tons | standalone; furnished and installed complete with startup | D11: 1 | E11: EA | F11: 3500 | G11: =D11*F11 -> 3500 | H11: D30 | I11: RS Means D3030; UFC 3-410-01
A12: 8 | B12: Mech | C12: Replace indoor VRF fan coil units ACP-3 zone | 14 EA ducted cassette type | mixed 2.2/2.0/2.8 KW | furnished and installed complete | D12: 14 | E12: EA | F12: 2800 | G12: =D12*F12 -> 39200 | H12: D30 | I12: RS Means D3050; qty and capacity confirmed ACP schedule 07 Mar 2026
A13: 9 | B13: Mech | C13: Replace indoor VRF fan coil units ACP-4 zone | 3 EA ducted cassette type | mixed 3.6/3.6/1.5 KW | furnished and installed complete | D13: 3 | E13: EA | F13: 2800 | G13: =D13*F13 -> 8400 | H13: D30 | I13: RS Means D3050; qty and capacity confirmed ACP schedule 07 Mar 2026
A14: 10 | B14: Mech | C14: Replace indoor VRF fan coil units ACP-5 zone | 4 EA ducted cassette type | mixed 4.5/4.4/6.0/11.2 KW | furnished and installed complete | D14: 4 | E14: EA | F14: 2800 | G14: =D14*F14 -> 11200 | H14: D30 | I14: RS Means D3050; qty and capacity confirmed ACP schedule 07 Mar 2026
A15: 11 | B15: Mech | C15: Replace indoor VRF fan coil units ACP-6 zone | 3 EA ducted cassette type | mixed 2.8/2.8/1.45 KW | furnished and installed complete | D15: 3 | E15: EA | F15: 2800 | G15: =D15*F15 -> 8400 | H15: D30 | I15: RS Means D3050; qty and capacity confirmed ACP schedule 07 Mar 2026
A16: 12 | B16: Mech | C16: Refrigerant piping | line sets | insulation | fittings | pressure testing | all 7 ACP systems complete | D16: 1 | E16: LS | F16: 20000 | G16: =D16*F16 -> 20000 | H16: D30 | I16: UFC 3-410-01; includes all branch piping to indoor fan coil units
... A19: 15 | B19: Mech | C19: Install new split unit HVAC | 1F and 2F hallways | 2 EA | capacity per designer load calculation | D19: 2 | E19: EA | F19: 12000 | G19: =D19*F19 -> 24000 | H19: D30 | I19: RS Means D3030; UFC 3-410-01; new hallway coverage both floors
G20: =SUM(G5:G19) -> 241800
A21: 2. MECHANICAL - DOAS FRESH AIR SYSTEMS - 4 Units + Ductwork Evaluation
A22: 16 | B22: Mech | C22: Replace ACP-1 100% outside air packaged unit | RM123 Mechanical Room 3 | serves main shop areas | furnished and installed complete with refrigerant lines, electrical, controls, and startup | D22: 1 | E22: EA | F22: 38000 | G22: =D22*F22 -> 38000 | H22: D30 | I22: RS Means D3060; 100% OA packaged unit; UFC 3-410-01; ASHRAE 62.1; AS-BUILT mech drawings confirmed
A23: 17 | B23: Mech | C23: Replace ACP-4-3 outside air processing unit | RM104 Office 1 | furnished and installed complete | D23: 1 | E23: EA | F23: 16000 | G23: =D23*F23 -> 16000 | H23: D30 | I23: RS Means D3060; outside air processing unit; UFC 3-410-01; location confirmed AS-BUILT mech drawings
A24: 18 | B24: Mech | C24: Replace ACP-5-4 outside air processing unit | RM207 Class Room | furnished and installed complete | D24: 1 | E24: EA | F24: 16000 | G24: =D24*F24 -> 16000 | H24: D30 | I24: RS Means D3060; UFC 3-410-01; location confirmed AS-BUILT mech drawings
A25: 19 | B25: Mech | C25: Replace ACP-6-3 outside air processing unit | RM116 Office 2 | furnished and installed complete | D25: 1 | E25: EA | F25: 16000 | G25: =D25*F25 -> 16000 | H25: D30 | I25: RS Means D3060; UFC 3-410-01; location confirmed AS-BUILT mech drawings
A26: 20 | B26: Mech | C26: Existing supply ductwork evaluation and replacement as required | all 4 DOAS systems | designer to confirm reuse vs. replacement per field assessment | D26: 1 | E26: LS | F26: 18000 | G26: =D26*F26 -> 18000 | H26: D30 | I26: UFC 3-410-01; ASHRAE 62.1; ductwork shown in AS-BUILT drawings; reuse determination by designer
G27: =SUM(G22:G26) -> 104000
A28: 3. MECHANICAL - EXHAUST SYSTEMS - 22 General Fans + 10 Hose Reels + Welding Exhaust Restore + RM114 Removal
A29: 21 | B29: Mech | C29: Replace general exhaust fans building-wide | 22 EA | FE-1,7,9,10,11,15,16,17 (restroom/shower/janitor) | FE-2,3,4 (storage/recycle) | FE-5,6,12 (shop) | FE-18,19,20,21,FS-1 (mechanical/battery/boiler) | FE-22,33,34 (bay/roof) | furnished and installed complete | designer evaluates duct reuse per room | D29: 22 | E29: EA | F29: 3000 | G29: =D29*F29 -> 66000 | H29: D30 | I29: RS Means D3090; UFC 3-410-01; 2010 vintage approaching EOL; quantities confirmed from mechanical equipment schedule FE-1 through FS-1
A30: 22 | B30: Mech | C30: Replace vehicle exhaust hose reel assemblies | 10 EA total | FE-23 through FE-28 in RM105 Maintenance Bay (6 EA) | FE-29 through FE-32 in RM113 Maintenance Bay (4 EA) | fan, reel assembly, and branch duct replacement complete | main exhaust header evaluation included | D30: 10 | E30: EA | F30: 5000 | G30: =D30*F30 -> 50000 | H30: D30 | I30: RS Means D3090; vehicle exhaust capture systems; UFC 3-410-01; quantities and locations confirmed from AS-BUILT mechanical drawings
A31: 23 | B31: Mech | C31: Full removal of abandoned dust collection system RM114 Wood Shop | exterior DC unit | wall penetration | all internal ductwork | 4 equipment connection points (miter saw, band saw, table saw, radial saw/sander) | debris disposal complete | D31: 1 | E31: LS | F31: 8500 | G31: =D31*F31 -> 8500 | H31: D30 | I31: RS Means D3090 demolition; UFC 3-410-01; full system extent confirmed from AS-BUILT mechanical drawings
A32: 24 | B32: Mech | C32: Repair and restore RM117 Welding Shop exhaust system | replace exhaust fans FE-13 and FE-14 | replace roof ventilator FA-1 | repair/replace welding exhaust hood and all associated ductwork | system originally designed for welding operations and has fallen into disrepair | D32: 1 | E32: LS | F32: 14000 | G32: =D32*F32 -> 14000 | H32: D30 | I32: RS Means D3090; UFC 3-410-01; system fully shown in AS-BUILT drawings as active design; confirmed repair required 19 Mar 2026
G33: =SUM(G29:G32) -> 138500
A34: 4. MECHANICAL - BATTERY ROOM - RM102 Ventilation and Conditioning Upgrade
A35: 25 | B35: Mech | C35: Battery room RM102 ventilation and conditioning upgrade | extend multizone split system to meet temperature requirements | upgrade existing wall exhaust fan FE-20 to code-compliant interlocked exhaust for hydrogen gas control | no existing hood or ductwork present | D35: 1 | E35: LS | F35: 12000 | G35: =D35*F35 -> 12000 | H35: D30 | I35: RS Means D3090/D5030; OSHA 1910.178(g); UFC 3-520-01; existing FE-20 wall propeller fan confirmed from AS-BUILT drawings; no duct or hood present
G36: =SUM(G35:G35) -> 12000
A37: 5. MECHANICAL - COMPRESSED AIR - RM119 System Inspection and Repair
A38: 26 | B38: Mech | C38: Compressed air system inspection, pressure testing, and repair as necessary | COM-1 compressor and air receiver in RM119 Mechanical Room 1 | full distribution loop through RM105, RM113, and shops RM101-104 | column-mounted air outlet drops throughout | D38: 1 | E38: LS | F38: 8500 | G38: =D38*F38 -> 8500 | H38: D30 | I38: RS Means D3090; system extent and layout confirmed from AS-BUILT compressed air plan drawings; repair as necessary
G39: =SUM(G38:G38) -> 8500
A40: 6. PLUMBING - Safety Stations and Fixtures
A41: 27 | B41: Plmb | C41: Replace emergency eyewash and shower stations building-wide | replace 4 EA E-2 eyewash stations (2x RM102 Battery Room, 2x RM105 Maintenance Bay) | replace 1 EA E-1 combo shower/eyewash in RM102 | add 2 emergency shower stations at RM105 locations currently equipped with eyewash only | all per ANSI Z358.1 distance requirements | D41: 1 | E41: LS | F41: 16000 | G41: =D41*F41 -> 16000 | H41: D20 | I41: RS Means D2010; ANSI Z358.1; UFC 3-420-01; fixture locations and types confirmed from AS-BUILT plumbing drawings
A42: 28 | B42: Plmb | C42: Replace 2F electric water cooler | RM214 corridor | EW-1 fixture tag | furnished and installed complete | D42: 1 | E42: EA | F42: 2800 | G42: =D42*F42 -> 2800 | H42: D20 | I42: RS Means D2020; UFC 3-420-01; fixture location confirmed from AS-BUILT plumbing drawings
...

Sheet PARAMETERS
A1: SCH-3270 | COST ESTIMATE PARAMETERS | LEVEL 3 ROM | FY27 | PAX ID 387568 | Fi Web BU26PPE74M
A2: PROJECT IDENTIFICATION
A3: Parameter | B3: Value | C3: Unit | D3: Source / Authority
A4: Estimate Title | B4: SCH-3270 Repair Mechanical / Electrical / Communications / Architectural | C4: Text | D4: DD Form 1391 | PAX ID 387568 | Fi Web BU26PPE74M
A5: Building / Installation | B5: SCH-3270 | Camp Schwab, Okinawa, Japan | C5: Text | D5: MCIPAC G-F PPE
A6: Supported Units | B6: 4th Marine Regiment | CLB-4 | C6: Text | D6: Primary: 4th MAR REGT | Secondary: CLB-4
A7: PAX ID | B7: 387568 | C7: ID | D7: PAX System
A8: Fi Web Project Number | B8: BU26PPE74M | C8: ID | D8: Fi Web - confirmed
A9: Primary Project CCN | B9: 21451 | C9: CCN | D9: CCN 21451 | Auto Organizational Shop | FAC 2141
A10: Estimate Date | B10: 19 Mar 2026 | C10: Date | D10: Date of estimate production
A11: Estimate Level | B11: Level 3 ROM | C11: UFS 3-740-05 | D11: Accuracy range not cited; For Information Only
A12: Delivery Method | B12: Design-Build (DB) | C12: Method
A14: COST INPUTS (Blue = user input)
A15: Parameter | B15: Value | C15: Unit | D15: Source / Authority
A16: Base Year | B16: 2024 | C16: FY | D16: FY24 CONUS base costs
A17: Target Fiscal Year | B17: 2027 | C17: FY | D17: FY27 construction start
A18: Area Cost Factor (ACF) | B18: 1.85 | C18: Multiplier | D18: UFC 3-701-01 w/Change 7 (25 Jul 2025), Table 4-1 OCONUS, M67400-0004
A19: Escalation Rate (annual) | B19: 0.021 | C19: % | D19: OSD FY25 published rate, client-confirmed; applies FY24 through FY27
A20: Escalation Years | B20: 3 | C20: Years | D20: FY24 base to FY27 target = 3 years
A21: General Requirements | B21: 0.1 | C21: % | D21: FSRM program-directed; UFC 3-701-01
A22: Contingency Rate | B22: 0.1 | C22: % | D22: Level 3 ROM - FSRM program-directed rate
A23: LSH Rate | B23: 0.025 | C23: % | D23: NAVFAC 11010.44E CH-1 | MCO 11000.12 (08 Sep 2014)
A24: Design Rate | B24: 0.06 | C24: % | D24: NAVFAC agency-directed - 6%
A25: SIOH Rate | B25: 0.08 | C25: % | D25: OCONUS FSRM customer-directed rate - 8.0% (NOT standard 7.3%)
A26: Construction Management (CM) | B26: 0.04 | C26: % | D26: NAVFAC agency-directed - 4%
A27: Design-Build Design | B27: 0.04 | C27: % | D27: Applied AFTER Total Funded per UFC 3-730-01 (2024)
A29: AREA (GSF) AND UFC UNIT COSTS
A30: Parameter | B30: Value | C30: Unit | D30: Source / Authority
A31: Total Building GSF | B31: 25390 | C31: SF | D31: iNFADS confirmed | Floor 1: 20,672 SF | Floor 2: 4,718 SF | CCN 21451
A32: RPUID | B32: 1174058 | C32: ID | D32: iNFADS | Camp Schwab | CCN 21451 | authoritative per DoW real property records
A33: Plant Replacement Value (PRV - iNFADS) | B33: 39507617 | C33: $ | D33: iNFADS RPUID 1174058 | confirmed | PRV taken directly; not computed via formula for this building
A34: LSH Allowance (2.5% of PRV) | B34: 987690 | C34: $ | D34: PRV x 2.5% | MCO 11000.12 (08 Sep 2014) | NAVFAC 11010.44E CH-1
A35: PUC (FAC 2141, CCN 21451 - Vehicle Maintenance Shop) | B35: 810 | C35: $/SF | D35: UFC 3-701-01 w/Change 7 (25 Jul 2025), Table 3, direct read | GUC: Military Vehicle Maintenance Small (<21,000 SF)
A37: DERIVED VALUES (Formula-driven - do not edit)
A38: Parameter | B38: Value | C38: Unit | D38: Formula Basis
A39: Compound Escalation Factor | B39: =(1+B19)^B20 -> 1.0643323 | C39: Factor | D39: (1 + 0.021)^3 = 1.0643322610 | live formula
A41: JPY/USD Exchange Rate | C41: Rate | D41: CONFIRM from Federal Reserve H.10 on date of PAX submission | JPY column is display-only; ROM chain is USD only
A43: KEY NOTES
A44: Escalation: OSD FY25 published rate 2.1%/yr confirmed. FY26/FY27 same rate applies per client direction.
A45: SIOH: 8.0% is the customer-directed OCONUS FSRM rate for MCIPAC G-F. This is NOT the standard OCONUS rate of 7.3%.
...

Sheet DD1391_BLOCK9
A1: SCH-3270 | COST ESTIMATE PARAMETERS | LEVEL 3 ROM | FY27 | PAX ID 387568 | Fi Web BU26PPE74M
A2: All amounts in $000s per DD Form 1391 convention. All formulas reference ESTIMATE tab. Carry to dollar; round only here.
A3: Cost Element | B3: Amount ($000s) | C3: Notes
A4: 1. Exterior Doors - Roll-up door inspection and repair (22 EA) | B4: =ROUND((SUMIF(SCOPE_DETAIL!H:H,"B20",SCOPE_DETAIL!G:G)/ESTIMATE!C4)*ESTIMATE!C7/1000,3) -> 47.65 | C4: Roll-up doors (B20) | 22 EA exterior vehicle bay doors | 2010 vintage
A5: 2. Interior Construction - Wall repair, anchor wire cables, restroom remediation | B5: =ROUND((SUMIF(SCOPE_DETAIL!H:H,"C10",SCOPE_DETAIL!G:G)/ESTIMATE!C4)*ESTIMATE!C7/1000,3) -> 93.134 | C5: Interior construction repairs (C10) | 3 architectural scope items
A6: 3. Interior Finishes - Ceiling tile replacement (2,500 SF) | B6: =ROUND((SUMIF(SCOPE_DETAIL!H:H,"C30",SCOPE_DETAIL!G:G)/ESTIMATE!C4)*ESTIMATE!C7/1000,3) -> 37.904 | C6: Interior finishes (C30) | mold/mildew ceiling tile replacement
A7: 4. Plumbing - Emergency safety stations and 2F water cooler | B7: =ROUND((SUMIF(SCOPE_DETAIL!H:H,"D20",SCOPE_DETAIL!G:G)/ESTIMATE!C4)*ESTIMATE!C7/1000,3) -> 40.719 | C7: Plumbing (D20) | eyewash/shower stations + water cooler RM214
A8: 5. Mechanical HVAC - ACP replacement, DOAS, exhaust systems, battery room, compressed air | B8: =ROUND((SUMIF(SCOPE_DETAIL!H:H,"D30",SCOPE_DETAIL!G:G)/ESTIMATE!C4)*ESTIMATE!C7/1000,3) -> 1093.354 | C8: HVAC/Mechanical (D30) | 27 scope items | ACP, DOAS, exhaust, battery room, compressed air
A9: 6. Electrical / Communications - Lighting, Cat6 NIPR drops, TR upgrades, MNS | B9: =ROUND((SUMIF(SCOPE_DETAIL!H:H,"D50",SCOPE_DETAIL!G:G)/ESTIMATE!C4)*ESTIMATE!C7/1000,3) -> 402.644 | C9: Electrical/Communications (D50) | lighting 94 fixtures | Cat6 70 drops | TR upgrades | MNS
A10: Subtotal (Base Direct x ACF x Escalation x General Requirements) | B10: =ESTIMATE!C7/1000 -> 1715.4056 | C10: From ESTIMATE tab C7 - pre-contingency subtotal
A11: Contingency (10.0%) - Level 3 ROM, FSRM Program-Directed | B11: =B10*PARAMETERS!B22 -> 171.54056 | C11: 10% of Gen Req-applied subtotal (row 10) | FSRM program-directed
A12: Life Safety and Health (LSH) - 2.5% of PRV | B12: =PARAMETERS!B34/1000 -> 987.69 | C12: PRV = $39,507,617 | iNFADS RPUID 1174058 | MCO 11000.12 | NAVFAC 11010.44E CH-1
A13: Design (6.0%) - Applied to Construction Base | B13: =ESTIMATE!C14/1000 -> 172.47816 | C13: 6.0% of Construction Base | NAVFAC agency-directed
A14: SIOH (8.0%) - OCONUS FSRM Customer-Directed Rate | B14: =ESTIMATE!C15/1000 -> 229.97088 | C14: 8.0% of Construction Base | OCONUS FSRM customer-directed (NOT standard 7.3%)
A15: Construction Management (4.0%) | B15: =ESTIMATE!C16/1000 -> 114.98544 | C15: 4.0% of Construction Base | NAVFAC agency-directed
A16: TOTAL FUNDED COST | B16: =ESTIMATE!C18/1000 -> 3392.07 | C16: Construction Base + Design + SIOH + CM
A18: CLASSIFICATION OF WORK
A19: Construction | B19: =B16 -> 3392.07 | C19: 100% of Total Funded | 10 U.S.C. Section 2802
A20: Special Interest: Restoration and Modernization | B20: =B16 -> 3392.07 | C20: 100% SRM | MCO 11000.12 | DoD 4270.5-M
A21: Design-Build Design (4.0%) - Applied AFTER Total Funded | B21: =ESTIMATE!C19/1000 -> 135.6828 | C21: UFC 3-730-01 (2024) | DB design applied after Total Funded per DD Form 1391 convention
A22: TOTAL PROJECT COST | B22: =ESTIMATE!C20/1000 -> 3527.7528 | C22: Total Funded + Design-Build Design
A24: LOCKED PARAMETERS (DO NOT CHANGE WITHOUT DIRECTION)
A25: ACF | C25: 1.85 - Camp Schwab per UFC 3-701-01 w/Change 7 (25 Jul 2025), Table 4-1, M67400-0004
A26: Escalation | C26: 2.1%/yr | FY24 to FY27 | (1.021)^3 = 1.0643 | OSD FY25 published rate
A27: General Requirements | C27: 10.0% | FSRM program-directed
A28: Contingency | C28: 10.0% | FSRM program-directed | Level 3 ROM
A29: SIOH | C29: 8.0% | OCONUS FSRM customer-directed (NOT standard 7.3%)
A30: Design | C30: 6.0% | NAVFAC agency-directed | applied to Construction Base
A31: CM | C31: 4.0% | NAVFAC agency-directed | applied to Construction Base
A32: DB Design | C32: 4.0% | Total Funded | applied AFTER Total Funded | UFC 3-730-01 (2024)
A33: Delivery Method | C33: Design-Build (DB)
